2020-04-15 15:20:23,762 DEBUG   MainThread:9340 [wandb_config.py:_load_defaults():122] no defaults not found in config-defaults.yaml
2020-04-15 15:20:23,863 DEBUG   MainThread:9340 [meta.py:setup():97] code probe starting
2020-04-15 15:20:23,863 DEBUG   MainThread:9340 [meta.py:setup():101] non time limited probe of code
2020-04-15 15:20:23,863 DEBUG   MainThread:9340 [meta.py:_setup_code_git():49] probe for git information
2020-04-15 15:20:23,971 DEBUG   MainThread:9340 [meta.py:_setup_code_program():58] save program starting
2020-04-15 15:20:23,972 DEBUG   MainThread:9340 [meta.py:_setup_code_program():60] save program starting: e:\Btech project\leaf-disease\tempCodeRunnerFile.py
2020-04-15 15:20:23,993 DEBUG   MainThread:9340 [meta.py:_setup_code_program():65] save program saved: E:\Btech project\leaf-disease\wandb\run-20200415_095022-h2hqtoj1\code\tempCodeRunnerFile.py
2020-04-15 15:20:23,993 DEBUG   MainThread:9340 [meta.py:_setup_code_program():67] save program
2020-04-15 15:20:23,997 DEBUG   MainThread:9340 [meta.py:setup():119] code probe done
2020-04-15 15:20:24,009 DEBUG   MainThread:9340 [run_manager.py:__init__():545] Initialized sync for leaf-disease/h2hqtoj1
2020-04-15 15:20:24,014 INFO    MainThread:9340 [run_manager.py:wrap_existing_process():1148] wrapping existing process 21444
2020-04-15 15:20:24,273 INFO    MainThread:9340 [run_manager.py:init_run():928] system metrics and metadata threads started
2020-04-15 15:20:24,273 INFO    MainThread:9340 [run_manager.py:init_run():967] upserting run before process can begin, waiting at most 10 seconds
2020-04-15 15:20:24,862 INFO    Thread-9  :9340 [run_manager.py:_on_file_modified():692] file/dir modified: E:\Btech project\leaf-disease\wandb\run-20200415_095022-h2hqtoj1\config.yaml
2020-04-15 15:20:25,332 INFO    Thread-22 :9340 [run_manager.py:_upsert_run():1052] saving patches
2020-04-15 15:20:26,272 INFO    Thread-22 :9340 [run_manager.py:_upsert_run():1056] saving pip packages
2020-04-15 15:20:26,277 INFO    Thread-22 :9340 [run_manager.py:_upsert_run():1058] initializing streaming files api
2020-04-15 15:20:26,278 INFO    Thread-22 :9340 [run_manager.py:_upsert_run():1065] unblocking file change observer, beginning sync with W&B servers
2020-04-15 15:20:26,278 INFO    MainThread:9340 [run_manager.py:wrap_existing_process():1165] informing user process we are ready to proceed
2020-04-15 15:20:26,297 INFO    MainThread:9340 [run_manager.py:_sync_etc():1272] entering loop for messages from user process
2020-04-15 15:20:26,297 INFO    MainThread:9340 [run_manager.py:_sync_etc():1295] received message from user process: {"exitcode": 0}
2020-04-15 15:20:26,299 INFO    MainThread:9340 [run_manager.py:_sync_etc():1381] closing log streams and sending exitcode to W&B
2020-04-15 15:20:26,301 INFO    MainThread:9340 [run_manager.py:shutdown():1072] shutting down system stats and metadata service
2020-04-15 15:20:26,777 INFO    Thread-9  :9340 [run_manager.py:_on_file_created():681] file/dir created: E:\Btech project\leaf-disease\wandb\run-20200415_095022-h2hqtoj1\output.log
2020-04-15 15:20:26,777 INFO    Thread-9  :9340 [run_manager.py:_on_file_created():681] file/dir created: E:\Btech project\leaf-disease\wandb\run-20200415_095022-h2hqtoj1\code\tempCodeRunnerFile.py
2020-04-15 15:20:26,778 INFO    Thread-9  :9340 [run_manager.py:_on_file_created():681] file/dir created: E:\Btech project\leaf-disease\wandb\run-20200415_095022-h2hqtoj1\wandb-metadata.json
2020-04-15 15:20:26,779 INFO    Thread-9  :9340 [run_manager.py:_on_file_created():681] file/dir created: E:\Btech project\leaf-disease\wandb\run-20200415_095022-h2hqtoj1\code
2020-04-15 15:20:26,884 INFO    Thread-9  :9340 [run_manager.py:_on_file_modified():692] file/dir modified: E:\Btech project\leaf-disease\wandb\run-20200415_095022-h2hqtoj1\output.log
2020-04-15 15:20:26,885 INFO    Thread-9  :9340 [run_manager.py:_on_file_created():681] file/dir created: E:\Btech project\leaf-disease\wandb\run-20200415_095022-h2hqtoj1\diff.patch
2020-04-15 15:20:26,887 INFO    Thread-9  :9340 [run_manager.py:_on_file_created():681] file/dir created: E:\Btech project\leaf-disease\wandb\run-20200415_095022-h2hqtoj1\wandb-events.jsonl
2020-04-15 15:20:26,888 INFO    Thread-9  :9340 [run_manager.py:_on_file_created():681] file/dir created: E:\Btech project\leaf-disease\wandb\run-20200415_095022-h2hqtoj1\requirements.txt
2020-04-15 15:20:27,278 INFO    MainThread:9340 [run_manager.py:shutdown():1084] stopping streaming files and file change observer
2020-04-15 15:20:27,885 INFO    Thread-9  :9340 [run_manager.py:_on_file_modified():692] file/dir modified: E:\Btech project\leaf-disease\wandb\run-20200415_095022-h2hqtoj1\wandb-metadata.json
2020-04-15 15:20:30,200 INFO    MainThread:9340 [run_manager.py:_sync_etc():1433] syncing files to cloud storage
2020-04-15 15:20:33,989 INFO    MainThread:9340 [run_manager.py:_sync_etc():1448] syncing complete: https://app.wandb.ai/abhiswain/leaf-disease/runs/h2hqtoj1
ified: E:\Btech project\leaf-disease\wandb\run-20200415_095022-h2hqtoj1\wandb-metadata2020-04-15 15:51:56,349 WARNING Thread-15 :5180 [util.py:request_with_retry():613] requests_with_retry encountered retryable exception: ('Connection aborted.', OSError("(10060, 'WSAETIMEDOUT')")). args: ('https://api.wandb.ai/files/abhiswain/leaf-disease/3rf6103s/file_stream',), kwargs: {'json': {'complete': False, 'failed': False}}
2020-04-15 17:23:29,325 WARNING Thread-15 :5180 [util.py:request_with_retry():613] requests_with_retry encountered retryable exception: ('Connection aborted.', OSError("(10060, 'WSAETIMEDOUT')")). args: ('https://api.wandb.ai/files/abhiswain/leaf-disease/3rf6103s/file_stream',), kwargs: {'json': {'complete': False, 'failed': False}}
2020-04-15 17:25:56,545 WARNING Thread-15 :5180 [util.py:request_with_retry():613] requests_with_retry encountered retryable exception: HTTPSConnectionPool(host='api.wandb.ai', port=443): Max retries exceeded with url: /files/abhiswain/leaf-disease/3rf6103s/file_stream (Caused by NewConnectionError('<urllib3.connection.VerifiedHTTPSConnection object at 0x0000027704BC8580>: Failed to establish a new connection: [WinError 10060] A connection attempt failed because the connected party did not properly respond after a period of time, or established connection failed because connected host has failed to respond')). args: ('https://api.wandb.ai/files/abhiswain/leaf-disease/3rf6103s/file_stream',), kwargs: {'json': {'complete': False, 'failed': False}}
2020-04-15 17:26:19,953 WARNING Thread-15 :5180 [util.py:request_with_retry():613] requests_with_retry encountered retryable exception: HTTPSConnectionPool(host='api.wandb.ai', port=443): Max retries exceeded with url: /files/abhiswain/leaf-disease/3rf6103s/file_stream (Caused by NewConnectionError('<urllib3.connection.VerifiedHTTPSConnection object at 0x0000027704BC82E0>: Failed to establish a new connection: [WinError 10060] A connection attempt failed because the connected party did not properly respond after a period of time, or established connection failed because connected host has failed to respond')). args: ('https://api.wandb.ai/files/abhiswain/leaf-disease/3rf6103s/file_stream',), kwargs: {'json': {'complete': False, 'failed': False}}
2020-04-15 17:29:48,560 WARNING Thread-15 :5180 [util.py:request_with_retry():613] requests_with_retry encountered retryable exception: ('Connection aborted.', OSError("(10060, 'WSAETIMEDOUT')")). args: ('https://api.wandb.ai/files/abhiswain/leaf-disease/3rf6103s/file_stream',), kwargs: {'json': {'complete': False, 'failed': False}}
2020-04-15 17:30:11,680 WARNING Thread-15 :5180 [util.py:request_with_retry():613] requests_with_retry encountered retryable exception: HTTPSConnectionPool(host='api.wandb.ai', port=443): Max retries exceeded with url: /files/abhiswain/leaf-disease/3rf6103s/file_stream (Caused by NewConnectionError('<urllib3.connection.VerifiedHTTPSConnection object at 0x0000027704B25B80>: Failed to establish a new connection: [WinError 10060] A connection attempt failed because the connected party did not properly respond after a period of time, or established connection failed because connected host has failed to respond')). args: ('https://api.wandb.ai/files/abhiswain/leaf-disease/3rf6103s/file_stream',), kwargs: {'json': {'complete': False, 'failed': False}}
2020-04-15 17:30:37,584 WARNING Thread-15 :5180 [util.py:request_with_retry():613] requests_with_retry encountered retryable exception: HTTPSConnectionPool(host='api.wandb.ai', port=443): Max retries exceeded with url: /files/abhiswain/leaf-disease/3rf6103s/file_stream (Caused by NewConnectionError('<urllib3.connection.VerifiedHTTPSConnection object at 0x0000027704B28C40>: Failed to establish a new connection: [WinError 10060] A connection attempt failed because the connected party did not properly respond after a period of time, or established connection failed because connected host has failed to respond')). args: ('https://api.wandb.ai/files/abhiswain/leaf-disease/3rf6103s/file_stream',), kwargs: {'json': {'complete': False, 'failed': False}}
2020-04-15 17:31:07,081 WARNING Thread-15 :5180 [util.py:request_with_retry():613] requests_with_retry encountered retryable exception: HTTPSConnectionPool(host='api.wandb.ai', port=443): Max retries exceeded with url: /files/abhiswain/leaf-disease/3rf6103s/file_stream (Caused by NewConnectionError('<urllib3.connection.VerifiedHTTPSConnection object at 0x0000027704B485E0>: Failed to establish a new connection: [WinError 10060] A connection attempt failed because the connected party did not properly respond after a period of time, or established connection failed because connected host has failed to respond')). args: ('https://api.wandb.ai/files/abhiswain/leaf-disease/3rf6103s/file_stream',), kwargs: {'json': {'complete': False, 'failed': False}}
2020-04-15 17:31:35,890 WARNING Thread-15 :5180 [util.py:request_with_retry():613] requests_with_retry encountered retryable exception: HTTPSConnectionPool(host='api.wandb.ai', port=443): Max retries exceeded with url: /files/abhiswain/leaf-disease/3rf6103s/file_stream (Caused by NewConnectionError('<urllib3.connection.VerifiedHTTPSConnection object at 0x0000027704B0D1F0>: Failed to establish a new connection: [WinError 10051] A socket operation was attempted to an unreachable network')). args: ('https://api.wandb.ai/files/abhiswain/leaf-disease/3rf6103s/file_stream',), kwargs: {'json': {'complete': False, 'failed': False}}
2020-04-15 18:34:15,107 WARNING Thread-15 :5180 [util.py:request_with_retry():613] requests_with_retry encountered retryable exception: ('Connection aborted.', OSError("(10060, 'WSAETIMEDOUT')")). args: ('https://api.wandb.ai/files/abhiswain/leaf-disease/3rf6103s/file_stream',), kwargs: {'json': {'complete': False, 'failed': False}}
2020-04-15 19:00:56,005 WARNING Thread-15 :5180 [util.py:request_with_retry():613] requests_with_retry encountered retryable exception: HTTPSConnectionPool(host='api.wandb.ai', port=443): Max retries exceeded with url: /files/abhiswain/leaf-disease/3rf6103s/file_stream (Caused by NewConnectionError('<urllib3.connection.VerifiedHTTPSConnection object at 0x0000027704BC4CA0>: Failed to establish a new connection: [WinError 10060] A connection attempt failed because the connected party did not properly respond after a period of time, or established connection failed because connected host has failed to respond')). args: ('https://api.wandb.ai/files/abhiswain/leaf-disease/3rf6103s/file_stream',), kwargs: {'json': {'complete': False, 'failed': False}}
2020-04-15 19:01:19,119 WARNING Thread-15 :5180 [util.py:request_with_retry():613] requests_with_retry encountered retryable exception: HTTPSConnectionPool(host='api.wandb.ai', port=443): Max retries exceeded with url: /files/abhiswain/leaf-disease/3rf6103s/file_stream (Caused by NewConnectionError('<urllib3.connection.VerifiedHTTPSConnection object at 0x0000027704BC8460>: Failed to establish a new connection: [WinError 10060] A connection attempt failed because the connected party did not properly respond after a period of time, or established connection failed because connected host has failed to respond')). args: ('https://api.wandb.ai/files/abhiswain/leaf-disease/3rf6103s/file_stream',), kwargs: {'json': {'complete': False, 'failed': False}}
2020-04-15 19:01:37,364 WARNING Thread-15 :5180 [util.py:request_with_retry():613] requests_with_retry encountered retryable exception: HTTPSConnectionPool(host='api.wandb.ai', port=443): Max retries exceeded with url: /files/abhiswain/leaf-disease/3rf6103s/file_stream (Caused by NewConnectionError('<urllib3.connection.VerifiedHTTPSConnection object at 0x0000027704BC8F10>: Failed to establish a new connection: [WinError 10051] A socket operation was attempted to an unreachable network')). args: ('https://api.wandb.ai/files/abhiswain/leaf-disease/3rf6103s/file_stream',), kwargs: {'json': {'complete': False, 'failed': False}}
2020-04-15 20:30:40,569 WARNING Thread-15 :5180 [util.py:request_with_retry():613] requests_with_retry encountered retryable exception: ('Connection aborted.', OSError("(10060, 'WSAETIMEDOUT')")). args: ('https://api.wandb.ai/files/abhiswain/leaf-disease/3rf6103s/file_stream',), kwargs: {'json': {'complete': False, 'failed': False}}
2020-04-15 20:43:42,848 WARNING Thread-15 :5180 [util.py:request_with_retry():613] requests_with_retry encountered retryable exception: ('Connection aborted.', OSError("(10060, 'WSAETIMEDOUT')")). args: ('https://api.wandb.ai/files/abhiswain/leaf-disease/3rf6103s/file_stream',), kwargs: {'json': {'complete': False, 'failed': False}}
2020-04-15 20:43:45,276 WARNING Thread-15 :5180 [util.py:request_with_retry():613] requests_with_retry encountered retryable exception: HTTPSConnectionPool(host='api.wandb.ai', port=443): Max retries exceeded with url: /files/abhiswain/leaf-disease/3rf6103s/file_stream (Caused by NewConnectionError('<urllib3.connection.VerifiedHTTPSConnection object at 0x0000027704BC8A00>: Failed to establish a new connection: [Errno 11001] getaddrinfo failed')). args: ('https://api.wandb.ai/files/abhiswain/leaf-disease/3rf6103s/file_stream',), kwargs: {'json': {'complete': False, 'failed': False}}
l.py:request_with_retry():613] requests_with_retry encountered retryable exception: ('Connection aborted.', OSError("(10060, 'WSAETIMEDOUT')")). args: ('https://api.wandb.ai/files/abhiswain/leaf-disease/3rf6103s/file_stream',), kwargs: {'json': {'complete': False, 'failed': False}}
2020-04-15 20:43:45,276 WARNING Thread-15 :5180 [3rf6103s:util.py:request_with_retry():613] requests_with_retry encountered retryable exception: HTTPSConnectionPool(host='api.wandb.ai', port=443): Max retries exceeded with url: /files/abhiswain/leaf-disease/3rf6103s/file_stream (Caused by NewConnectionError('<urllib3.connection.VerifiedHTTPSConnection object at 0x0000027704BC8A00>: Failed to establish a new connection: [Errno 11001] getaddrinfo failed')). args: ('https://api.wandb.ai/files/abhiswain/leaf-disease/3rf6103s/file_stream',), kwargs: {'json': {'complete': False, 'failed': False}}
