2020-03-21 15:36:52,025 INFO DSC_0366(masks) matches DSC_0366(image superpixels) 

2020-03-21 15:36:52,025 INFO Loading image.......
2020-03-21 15:36:52,051 INFO Separating segments....
2020-03-21 15:36:54,344 INFO Superpixel 35 is diseased with Bacterial Leaf blight
2020-03-21 15:36:54,609 INFO Superpixel 39 is diseased with Bacterial Leaf blight
2020-03-21 15:36:54,652 INFO Superpixel 40 is diseased with Bacterial Leaf blight
2020-03-21 15:36:54,739 INFO Superpixel 42 is diseased with Bacterial Leaf blight
2020-03-21 15:36:55,095 INFO Superpixel 47 is diseased with Bacterial Leaf blight
2020-03-21 15:36:55,187 INFO Superpixel 48 is diseased with Bacterial Leaf blight
2020-03-21 15:36:55,262 INFO Superpixel 49 is diseased with Bacterial Leaf blight
2020-03-21 15:36:55,487 INFO Superpixel 53 is diseased with Bacterial Leaf blight
2020-03-21 15:36:55,532 INFO Superpixel 54 is diseased with Bacterial Leaf blight
2020-03-21 15:36:55,585 INFO Superpixel 55 is diseased with Bacterial Leaf blight
2020-03-21 15:36:55,674 INFO Superpixel 56 is diseased with Bacterial Leaf blight
2020-03-21 15:36:55,749 INFO Superpixel 57 is diseased with Bacterial Leaf blight
2020-03-21 15:36:57,270 INFO DSC_0366 done 

2020-03-21 15:36:57,290 INFO DSC_0367(masks) matches DSC_0367(image superpixels) 

2020-03-21 15:36:57,290 INFO Loading image.......
2020-03-21 15:36:57,353 INFO Separating segments....
2020-03-21 15:36:57,833 ERROR Exception at %s
Traceback (most recent call last):
  File "C:/Users/Abhishek Swain/PycharmProjects/leaf-disease/slic.py", line 121, in binary_label
    binary.create_dataset(f'spxl{i}_{mode}', data=spxl)
  File "C:\Users\Abhishek Swain\Anaconda3\envs\myenv\lib\site-packages\h5py\_hl\group.py", line 119, in create_dataset
    self[name] = dset
  File "C:\Users\Abhishek Swain\Anaconda3\envs\myenv\lib\site-packages\h5py\_hl\group.py", line 287, in __setitem__
    h5o.link(obj.id, self.id, name, lcpl=lcpl, lapl=self._lapl)
  File "h5py\_objects.pyx", line 54, in h5py._objects.with_phil.wrapper
  File "h5py\_objects.pyx", line 55, in h5py._objects.with_phil.wrapper
  File "h5py\h5o.pyx", line 202, in h5py.h5o.link
RuntimeError: Unable to create link (name already exists)
2020-03-21 15:36:57,835 INFO [COMPLETED] in 0.09766892592112224 minutes
